Workbook
Name alpha: Parameters!$B$3
Name bounds: Parameters!$B$10:$B$13
Name delta: Parameters!$B$4
Name max_year_gap: Parameters!$B$5

Sheet README
A1: UA-CEE workbook: hand-checkable calculations of the paper
A3: Every number on the calculation sheets is an Excel formula. Blue cells are values copied from the official API responses stored in data/raw (each row has its link); yellow cells on Parameters may be changed and every sheet recalculates.
A5: Sheets
A6: Parameters: weak-link penalty alpha and delta, maturity-level bounds, maximum year gap for the year-aligned check.
A7: Farm_EU_data: Eurostat IFS 2023, share of holdings using ten digital technologies, all and large holdings, all 27 member states and EU-27; the EU leader of each technology is found with MAX/INDEX/MATCH.
A8: Farm_UA_data: Derzhstat 2025, number of enterprises using each technology and number of enterprises with agricultural land; the Ukrainian share is an estimate (numerator and denominator come from different surveys). For the large-holding basis the four livestock technologies are divided by the number of enterprises keeping farm animals (Derzhstat, 2024), because the EU large-holding livestock shares are shares of livestock holdings.
A9: Farm_results: shares and ratios to the EU, median ratios, partial layer scores DM_C (robotics) and DM_L3 (nine precision technologies) for both EU bases.
A10: Processing_data: food processing (NACE C10-C12), 17 indicator pairs Eurostat / Derzhstat with the values of all 27 member states, EU-27 and Ukraine; leader (MAX) and minimum (MIN) over the member states.
A11: Processing_index: indicator scores P / P_leader, layer scores, ADMI_base, weakest layer, penalty, ADMI, maturity level, DM_I, DM_S and ranks.
A12: TOPSIS: robustness check with entropy and equal weights, Spearman and Pearson correlations with ADMI.
A13: Orientations: mean profiles of the CEE countries at levels 3 and 4 and the gap of Ukraine to level 3.
A14: Normalisation_check: the same index with min-max normalisation over the member states, ranks and Spearman correlation.
... A29: Spearman correlations use 1 - 6 * sum(d^2) / (n (n^2 - 1)) with n = 10 (nine CEE countries and Ukraine).

Sheet Parameters
A1: Parameters (yellow cells may be changed)
A3: alpha | B3: 0.4 | C3: weak-link penalty strength
A4: delta | B4: 0.375 | C4: weak-link threshold
A5: max_year_gap | B5: 1 | C5: Sensitivity: largest allowed difference between the EU and Ukrainian years of an indicator pair
A9: level bounds
B10: 0.2
B11: 0.4
B12: 0.6
B13: 0.8

Sheet Farm_EU_data
A1: Eurostat IFS 2023: share of holdings using the technology, % (holdings above the survey thresholds)
A3: all holdings
A4: Technology | B4: Eurostat dataset | C4: Code | D4: AT | E4: BE | F4: BG | G4: CY | H4: CZ | I4: DE | J4: DK | K4: EE | L4: EL | M4: ES | N4: FI | O4: FR | P4: HR | Q4: HU | R4: IE | S4: IT | T4: LT | U4: LU | V4: LV | W4: MT | X4: NL | Y4: PL | Z4: PT | AA4: RO | AB4: SE | AC4: SI | AD4: SK | AE4: EU27_2020 | AF4: Leader value | AG4: Leader | AH4: Link
A5: ROBOTICS | B5: ef_mp_digi | C5: MAC_ROB | D5: 3.84 | E5: 21.19 | F5: 0.56 | G5: 0.5 | H5: 3.41 | I5: 18.26 | J5: 21.11 | K5: 8.03 | L5: 0.43 | M5: 15.35 | N5: 19.15 | O5: 22.42 | P5: 2.08 | Q5: 2.62 | R5: 8 | S5: 4.46 | T5: 0.46 | U5: 24.02 | V5: 4.68 | W5: 3.69 | X5: 35.02 | Y5: 1.34 | Z5: 0.39 | AA5: 3.26 | AB5: 12.22 | AC5: 1.59 | AD5: 1.31 | AE5: 6.79 | AF5: =MAX(D5:AD5) -> 35.02 | AG5: =INDEX($D$4:$AD$4,MATCH(AF5,D5:AD5,0)) -> NL | AH5: https://doi.org/10.2908/EF_MP_DIGI
A6: MAC_ROB_PPP | B6: ef_mp_digicr | C6: MAC_ROB_PPP | D6: 0.08 | E6: 6.23 | F6: 0.26 | G6: 0.04 | H6: 0.86 | I6: 3.27 | J6: 19.65 | K6: 5.04 | L6: 0.1 | M6: 1.91 | N6: 12.43 | O6: 12.98 | P6: 0.18 | Q6: 1.01 | R6: 7.52 | S6: 0.11 | T6: 0.05 | U6: 2.86 | V6: 2.72 | X6: 6.75 | Y6: 0.22 | Z6: 0.21 | AA6: 0.14 | AB6: 4.73 | AD6: 0.59 | AE6: 1.76 | AF6: =MAX(D6:AD6) -> 19.65 | AG6: =INDEX($D$4:$AD$4,MATCH(AF6,D6:AD6,0)) -> DK | AH6: https://doi.org/10.2908/EF_MP_DIGICR
A7: BAND_SPRAY_PPP | B7: ef_mp_digicr | C7: MAC_BDS_PPP | D7: 2.35 | E7: 7.68 | F7: 0.29 | G7: 0.02 | H7: 0.76 | I7: 7.7 | J7: 2.61 | K7: 4.75 | L7: 3.17 | M7: 7.26 | N7: 2.92 | O7: 4.98 | P7: 4.83 | Q7: 3.34 | R7: 3.21 | S7: 0.14 | T7: 0.43 | U7: 9.14 | V7: 1.39 | W7: 0.39 | X7: 3.43 | Y7: 12.66 | Z7: 0.72 | AA7: 0.45 | AB7: 1.28 | AD7: 0.18 | AE7: 4.21 | AF7: =MAX(D7:AD7) -> 12.66 | AG7: =INDEX($D$4:$AD$4,MATCH(AF7,D7:AD7,0)) -> PL | AH7: https://doi.org/10.2908/EF_MP_DIGICR
A8: VAR_RATE_TECH | B8: ef_mp_digicr | C8: MAC_VRT | D8: 6.44 | E8: 9.22 | F8: 0.9 | G8: 0.08 | H8: 3.36 | I8: 18.59 | J8: 11.18 | K8: 9.6 | L8: 1.59 | M8: 3.99 | N8: 9.05 | O8: 3.87 | P8: 1.9 | Q8: 5.8 | R8: 2.49 | S8: 4.28 | T8: 0.87 | U8: 15.43 | V8: 4.08 | W8: 3.12 | X8: 11.32 | Y8: 13.69 | Z8: 0.36 | AA8: 0.78 | AB8: 4.81 | AD8: 0.71 | AE8: 5.32 | AF8: =MAX(D8:AD8) -> 18.59 | AG8: =INDEX($D$4:$AD$4,MATCH(AF8,D8:AD8,0)) -> DE | AH8: https://doi.org/10.2908/EF_MP_DIGICR
A9: PREC_MON_CROPS | B9: ef_mp_digicr | C9: MAC_PMON_CR | D9: 1.88 | E9: 6.54 | F9: 0.43 | G9: 0.04 | H9: 1.77 | I9: 20.96 | J9: 4.59 | K9: 4.66 | L9: 0.36 | M9: 2.47 | N9: 9.43 | O9: 13.45 | P9: 0.73 | Q9: 5.32 | R9: 1.7 | S9: 1.61 | T9: 0.82 | U9: 4 | V9: 1.09 | W9: 3.12 | X9: 2.67 | Y9: 2.82 | Z9: 1.13 | AA9: 0.37 | AB9: 1.21 | AC9: 0.68 | AD9: 0.41 | AE9: 3.23 | AF9: =MAX(D9:AD9) -> 20.96 | AG9: =INDEX($D$4:$AD$4,MATCH(AF9,D9:AD9,0)) -> DE | AH9: https://doi.org/10.2908/EF_MP_DIGICR
A10: SOIL_ANALYSIS | B10: ef_mp_digicr | C10: MAC_ASOIL | D10: 9.38 | E10: 46.39 | F10: 1.59 | G10: 0.08 | H10: 1.34 | I10: 37.79 | J10: 24.86 | K10: 29.75 | L10: 2.43 | M10: 10.11 | N10: 58.25 | O10: 41.33 | P10: 9.64 | Q10: 5.59 | R10: 40.58 | S10: 6.25 | T10: 2.37 | U10: 63.43 | V10: 5.47 | W10: 26.56 | X10: 1.71 | Y10: 12.31 | Z10: 10.2 | AA10: 0.3 | AB10: 11.68 | AC10: 13.89 | AD10: 0.65 | AE10: 11.35 | AF10: =MAX(D10:AD10) -> 63.43 | AG10: =INDEX($D$4:$AD$4,MATCH(AF10,D10:AD10,0)) -> LU | AH10: https://doi.org/10.2908/EF_MP_DIGICR
A11: AUTO_FEED_SYS | B11: ef_mp_digilsk | C11: MAC_AFDS | D11: 10.88 | E11: 11.61 | F11: 0.36 | G11: 0.83 | H11: 1.69 | I11: 12.01 | J11: 8.96 | K11: 2.05 | L11: 0.22 | M11: 2.87 | N11: 6.49 | O11: 5.84 | P11: 0.5 | Q11: 1.5 | S11: 1.29 | T11: 0.19 | U11: 15.08 | V11: 0.29 | W11: 3.32 | X11: 15.17 | Y11: 1.98 | Z11: 0.89 | AA11: 0.37 | AB11: 6.05 | AC11: 1.38 | AD11: 0.63 | AE11: 2.44 | AF11: =MAX(D11:AD11) -> 15.17 | AG11: =INDEX($D$4:$AD$4,MATCH(AF11,D11:AD11,0)) -> NL | AH11: https://doi.org/10.2908/EF_MP_DIGILSK
A12: MILK_ROBOTS | B12: ef_mp_digilsk | C12: MAC_MLK_ROB | D12: 1.88 | E12: 2.85 | F12: 0.01 | G12: 0.46 | H12: 0.75 | I12: 3.46 | J12: 2.22 | K12: 0.75 | L12: 0.2 | M12: 2.75 | N12: 3.29 | O12: 2.13 | P12: 1.27 | Q12: 0.23 | S12: 3.41 | T12: 0.1 | U12: 12.29 | V12: 0.53 | W12: 0.18 | X12: 9.6 | Y12: 0.06 | Z12: 0.07 | AA12: 2.87 | AB12: 2.23 | AC12: 1.13 | AD12: 0.03 | AE12: 1.96 | AF12: =MAX(D12:AD12) -> 12.29 | AG12: =INDEX($D$4:$AD$4,MATCH(AF12,D12:AD12,0)) -> LU | AH12: https://doi.org/10.2908/EF_MP_DIGILSK
A13: MON_ANIMALS | B13: ef_mp_digilsk | C13: MAC_WHMON | D13: 16.76 | E13: 17.76 | F13: 3.08 | G13: 0.83 | H13: 2.71 | I13: 11.02 | J13: 11.82 | K13: 9.62 | L13: 0.16 | M13: 6.2 | N13: 6.16 | O13: 19.76 | P13: 4.16 | Q13: 2.58 | S13: 3.67 | T13: 1.21 | U13: 27.37 | V13: 1.78 | W13: 3.69 | X13: 20.85 | Y13: 3.21 | Z13: 0.89 | AA13: 0.38 | AB13: 12.08 | AC13: 2.86 | AD13: 0.68 | AE13: 4.69 | AF13: =MAX(D13:AD13) -> 27.37 | AG13: =INDEX($D$4:$AD$4,MATCH(AF13,D13:AD13,0)) -> LU | AH13: https://doi.org/10.2908/EF_MP_DIGILSK
A14: AUTO_REG_CLIMATE | B14: ef_mp_digilsk | C14: MAC_AREG | D14: 9.64 | E14: 11.58 | F14: 0.53 | G14: 0.54 | H14: 2.14 | I14: 11.67 | J14: 9.09 | K14: 1.87 | L14: 0.14 | M14: 2 | N14: 9.73 | O14: 8.58 | P14: 0.3 | Q14: 0.85 | S14: 1.47 | T14: 0.17 | U14: 12.29 | V14: 0.43 | W14: 5.54 | X14: 15.84 | Y14: 2.13 | Z14: 0.78 | AA14: 0.17 | AB14: 8.56 | AC14: 1.92 | AD14: 0.46 | AE14: 2.51 | AF14: =MAX(D14:AD14) -> 15.84 | AG14: =INDEX($D$4:$AD$4,MATCH(AF14,D14:AD14,0)) -> NL | AH14: https://doi.org/10.2908/EF_MP_DIGILSK
A17: large holdings
A18: Technology | B18: Eurostat dataset | C18: Code | D18: AT | E18: BE | F18: BG | G18: CY | H18: CZ | I18: DE | J18: DK | K18: EE | L18: EL | M18: ES | N18: FI | O18: FR | P18: HR | Q18: HU | R18: IE | S18: IT | T18: LT | U18: LU | V18: LV | W18: MT | X18: NL | Y18: PL | Z18: PT | AA18: RO | AB18: SE | AC18: SI | AD18: SK | AE18: EU27_2020 | AF18: Leader value | AG18: Leader | AH18: Link
A19: ROBOTICS | B19: ef_mp_digi | C19: MAC_ROB | D19: 13.86 | E19: 33.35 | F19: 5.15 | G19: 5.15 | H19: 14.61 | I19: 42.06 | J19: 47.24 | K19: 34.59 | L19: 7.47 | M19: 39.78 | N19: 55.12 | O19: 39.31 | P19: 16.56 | Q19: 14.83 | R19: 27.23 | S19: 23.14 | T19: 5.1 | U19: 42.27 | V19: 40.82 | W19: 31.58 | X19: 48.33 | Y19: 7.21 | Z19: 4.29 | AA19: 17.22 | AB19: 47.04 | AC19: 14 | AD19: 7.42 | AE19: 31.3 | AF19: =MAX(D19:AD19) -> 55.12 | AG19: =INDEX($D$18:$AD$18,MATCH(AF19,D19:AD19,0)) -> FI | AH19: https://doi.org/10.2908/EF_MP_DIGI
A20: MAC_ROB_PPP | B20: ef_mp_digicr | C20: MAC_ROB_PPP | D20: 0.2 | E20: 13.58 | F20: 2.27 | H20: 3.72 | I20: 10 | J20: 51.23 | K20: 18.27 | L20: 2.11 | M20: 5.4 | N20: 32.71 | O20: 32.18 | P20: 2.7 | Q20: 4.51 | R20: 23.31 | S20: 1.59 | T20: 0.51 | U20: 7.55 | V20: 21.34 | X20: 22.19 | Y20: 3.96 | Z20: 2.64 | AA20: 1.28 | AB20: 18.49 | AD20: 3.53 | AE20: 16.55 | AF20: =MAX(D20:AD20) -> 51.23 | AG20: =INDEX($D$18:$AD$18,MATCH(AF20,D20:AD20,0)) -> DK | AH20: https://doi.org/10.2908/EF_MP_DIGICR
A21: BAND_SPRAY_PPP | B21: ef_mp_digicr | C21: MAC_BDS_PPP | D21: 3.25 | E21: 10.93 | F21: 1.73 | H21: 3.19 | I21: 12.41 | J21: 5.77 | K21: 13.46 | L21: 7.37 | M21: 11.25 | N21: 4.07 | O21: 5.03 | P21: 13.51 | Q21: 13.95 | R21: 6.84 | S21: 1.15 | T21: 4.04 | U21: 18.87 | V21: 9.51 | X21: 11.25 | Y21: 23.44 | Z21: 4.69 | AA21: 4.92 | AB21: 3.35 | AD21: 1.18 | AE21: 8.07 | AF21: =MAX(D21:AD21) -> 23.44 | AG21: =INDEX($D$18:$AD$18,MATCH(AF21,D21:AD21,0)) -> PL | AH21: https://doi.org/10.2908/EF_MP_DIGICR
A22: VAR_RATE_TECH | B22: ef_mp_digicr | C22: MAC_VRT | D22: 21.54 | E22: 16.89 | F22: 7.2 | G22: 2.33 | H22: 15.58 | I22: 45.76 | J22: 32.9 | K22: 32.21 | L22: 7.37 | M22: 6.95 | N22: 27.39 | O22: 10.24 | P22: 2.7 | Q22: 26.86 | R22: 8.53 | S22: 13.19 | T22: 8.75 | U22: 28.3 | V22: 29.56 | X22: 33.13 | Y22: 26.26 | Z22: 5.43 | AA22: 9.9 | AB22: 23.2 | AD22: 4.31 | AE22: 16.74 | AF22: =MAX(D22:AD22) -> 45.76 | AG22: =INDEX($D$18:$AD$18,MATCH(AF22,D22:AD22,0)) -> DE | AH22: https://doi.org/10.2908/EF_MP_DIGICR
A23: PREC_MON_CROPS | B23: ef_mp_digicr | C23: MAC_PMON_CR | D23: 7.72 | E23: 17.55 | F23: 2.13 | H23: 8.32 | I23: 50.76 | J23: 14.57 | K23: 16.35 | L23: 6.32 | M23: 6.57 | N23: 20.97 | O23: 23.92 | P23: 8.78 | Q23: 23.57 | R23: 5.27 | S23: 9.82 | T23: 7.74 | U23: 7.55 | V23: 8.48 | X23: 11.55 | Y23: 16.32 | Z23: 11.58 | AA23: 5.11 | AB23: 6.08 | AC23: 11.76 | AD23: 2.35 | AE23: 18.73 | AF23: =MAX(D23:AD23) -> 50.76 | AG23: =INDEX($D$18:$AD$18,MATCH(AF23,D23:AD23,0)) -> DE | AH23: https://doi.org/10.2908/EF_MP_DIGICR
A24: SOIL_ANALYSIS | B24: ef_mp_digicr | C24: MAC_ASOIL | D24: 28.05 | E24: 62.58 | F24: 6.27 | H24: 5.84 | I24: 66.27 | J24: 60.89 | K24: 73.08 | L24: 11.58 | M24: 18.75 | N24: 73.08 | O24: 68.42 | P24: 45.27 | Q24: 26.08 | R24: 59.7 | S24: 19.73 | T24: 17 | U24: 86.79 | V24: 28.53 | X24: 7.29 | Y24: 46.34 | Z24: 42.38 | AA24: 6.39 | AB24: 44.79 | AC24: 58.82 | AD24: 3.14 | AE24: 45.73 | AF24: =MAX(D24:AD24) -> 86.79 | AG24: =INDEX($D$18:$AD$18,MATCH(AF24,D24:AD24,0)) -> LU | AH24: https://doi.org/10.2908/EF_MP_DIGICR
A25: AUTO_FEED_SYS | B25: ef_mp_digilsk | C25: MAC_AFDS | D25: 75.31 | E25: 38.98 | F25: 15.45 | G25: 31.82 | H25: 20.77 | I25: 54.89 | J25: 59.05 | K25: 37.97 | L25: 14.83 | M25: 43.56 | N25: 48.42 | O25: 26.16 | P25: 38.24 | Q25: 41.18 | S25: 46.23 | T25: 14.1 | U25: 38.02 | V25: 12.28 | X25: 43.29 | Y25: 59.94 | Z25: 35.31 | AA25: 27.62 | AB25: 60.96 | AC25: 50.51 | AD25: 10.71 | AE25: 37.24 | AF25: =MAX(D25:AD25) -> 75.31 | AG25: =INDEX($D$18:$AD$18,MATCH(AF25,D25:AD25,0)) -> AT | AH25: https://doi.org/10.2908/EF_MP_DIGILSK
A26: MILK_ROBOTS | B26: ef_mp_digilsk | C26: MAC_MLK_ROB | D26: 11.28 | E26: 9.38 | F26: 0.81 | G26: 10.23 | H26: 8.7 | I26: 16.88 | J26: 15.71 | K26: 17.72 | L26: 3.23 | M26: 15.5 | N26: 32.84 | O26: 11.39 | P26: 6.62 | Q26: 4.41 | S26: 41.36 | T26: 7.69 | U26: 32.23 | V26: 19.3 | X26: 24.54 | Y26: 4.25 | Z26: 3.33 | AA26: 40.95 | AB26: 30.21 | AD26: 1.19 | AE26: 14.6 | AF26: =MAX(D26:AD26) -> 41.36 | AG26: =INDEX($D$18:$AD$18,MATCH(AF26,D26:AD26,0)) -> IT | AH26: https://doi.org/10.2908/EF_MP_DIGILSK
A27: MON_ANIMALS | B27: ef_mp_digilsk | C27: MAC_WHMON | D27: 75.31 | E27: 42.6 | F27: 39.02 | G27: 34.09 | H27: 35.75 | I27: 40.54 | J27: 70 | K27: 65.82 | L27: 12.17 | M27: 53.81 | N27: 51.79 | O27: 70.68 | P27: 39.71 | Q27: 50.49 | S27: 63.17 | T27: 32.05 | U27: 61.16 | V27: 33.33 | X27: 54.26 | Y27: 46.88 | Z27: 28.4 | AA27: 18.57 | AB27: 53.74 | AC27: 50.51 | AD27: 10.71 | AE27: 49.07 | AF27: =MAX(D27:AD27) -> 75.31 | AG27: =INDEX($D$18:$AD$18,MATCH(AF27,D27:AD27,0)) -> AT | AH27: https://doi.org/10.2908/EF_MP_DIGILSK
A28: AUTO_REG_CLIMATE | B28: ef_mp_digilsk | C28: MAC_AREG | D28: 75.08 | E28: 39.55 | F28: 19.51 | G28: 22.73 | H28: 28.99 | I28: 51.02 | J28: 58.1 | K28: 37.97 | L28: 12.93 | M28: 33.79 | N28: 60.63 | O28: 36.52 | P28: 29.41 | Q28: 34.8 | S28: 55.57 | T28: 12.82 | U28: 33.06 | V28: 15.79 | X28: 47.17 | Y28: 54.25 | Z28: 32.84 | AA28: 14.76 | AB28: 59.09 | AC28: 50.51 | AD28: 8.33 | AE28: 38.52 | AF28: =MAX(D28:AD28) -> 75.08 | AG28: =INDEX($D$18:$AD$18,MATCH(AF28,D28:AD28,0)) -> AT | AH28: https://doi.org/10.2908/EF_MP_DIGILSK

Sheet Farm_UA_data
A1: Derzhstat 2025: enterprises (incl. family farms) using the technology; share = estimate
A3: Technology | B3: Enterprises using | C3: Enterprises with agricultural land | D3: Estimated share, % | E3: Numerator link | F3: Denominator link | G3: Enterprises keeping farm animals (2024) | H3: Estimated share, large-holding basis, % | I3: Livestock denominator link
A4: ROBOTICS | B4: 1193 | C4: 30201 | D4: =100*B4/C4 -> 3.9502003 | E4: https://stat.gov.ua/uk/explorer?urn=SSSU%3ADF_AGR_MACHINERY_AVAILABILITY%28~%29 | F4: https://stat.gov.ua/uk/explorer?urn=SSSU%3ADF_AREA_HARVESTS_CROP_YIELD_A%28~%29 | H4: =IF(G4="",D4,100*B4/G4) -> 3.9502003
A5: MAC_ROB_PPP | B5: 911 | C5: 30201 | D5: =100*B5/C5 -> 3.0164564 | E5: https://stat.gov.ua/uk/explorer?urn=SSSU%3ADF_AGR_MACHINERY_AVAILABILITY%28~%29 | F5: https://stat.gov.ua/uk/explorer?urn=SSSU%3ADF_AREA_HARVESTS_CROP_YIELD_A%28~%29 | H5: =IF(G5="",D5,100*B5/G5) -> 3.0164564
A6: BAND_SPRAY_PPP | B6: 420 | C6: 30201 | D6: =100*B6/C6 -> 1.3906824 | E6: https://stat.gov.ua/uk/explorer?urn=SSSU%3ADF_AGR_MACHINERY_AVAILABILITY%28~%29 | F6: https://stat.gov.ua/uk/explorer?urn=SSSU%3ADF_AREA_HARVESTS_CROP_YIELD_A%28~%29 | H6: =IF(G6="",D6,100*B6/G6) -> 1.3906824
A7: VAR_RATE_TECH | B7: 391 | C7: 30201 | D7: =100*B7/C7 -> 1.2946591 | E7: https://stat.gov.ua/uk/explorer?urn=SSSU%3ADF_AGR_MACHINERY_AVAILABILITY%28~%29 | F7: https://stat.gov.ua/uk/explorer?urn=SSSU%3ADF_AREA_HARVESTS_CROP_YIELD_A%28~%29 | H7: =IF(G7="",D7,100*B7/G7) -> 1.2946591
A8: PREC_MON_CROPS | B8: 888 | C8: 30201 | D8: =100*B8/C8 -> 2.9403 | E8: https://stat.gov.ua/uk/explorer?urn=SSSU%3ADF_AGR_MACHINERY_AVAILABILITY%28~%29 | F8: https://stat.gov.ua/uk/explorer?urn=SSSU%3ADF_AREA_HARVESTS_CROP_YIELD_A%28~%29 | H8: =IF(G8="",D8,100*B8/G8) -> 2.9403
A9: SOIL_ANALYSIS | B9: 349 | C9: 30201 | D9: =100*B9/C9 -> 1.1555909 | E9: https://stat.gov.ua/uk/explorer?urn=SSSU%3ADF_AGR_MACHINERY_AVAILABILITY%28~%29 | F9: https://stat.gov.ua/uk/explorer?urn=SSSU%3ADF_AREA_HARVESTS_CROP_YIELD_A%28~%29 | H9: =IF(G9="",D9,100*B9/G9) -> 1.1555909
A10: AUTO_FEED_SYS | B10: 367 | C10: 30201 | D10: =100*B10/C10 -> 1.2151915 | E10: https://stat.gov.ua/uk/explorer?urn=SSSU%3ADF_AGR_MACHINERY_AVAILABILITY%28~%29 | F10: https://stat.gov.ua/uk/explorer?urn=SSSU%3ADF_AREA_HARVESTS_CROP_YIELD_A%28~%29 | G10: 2070 | H10: =IF(G10="",D10,100*B10/G10) -> 17.729469 | I10: https://stat.gov.ua/uk/explorer?urn=SSSU%3ADF_STOCKBREEDING_FODDER_A%28~%29
A11: MILK_ROBOTS | B11: 74 | C11: 30201 | D11: =100*B11/C11 -> 0.245025 | E11: https://stat.gov.ua/uk/explorer?urn=SSSU%3ADF_AGR_MACHINERY_AVAILABILITY%28~%29 | F11: https://stat.gov.ua/uk/explorer?urn=SSSU%3ADF_AREA_HARVESTS_CROP_YIELD_A%28~%29 | G11: 2070 | H11: =IF(G11="",D11,100*B11/G11) -> 3.5748792 | I11: https://stat.gov.ua/uk/explorer?urn=SSSU%3ADF_STOCKBREEDING_FODDER_A%28~%29
A12: MON_ANIMALS | B12: 198 | C12: 30201 | D12: =100*B12/C12 -> 0.65560743 | E12: https://stat.gov.ua/uk/explorer?urn=SSSU%3ADF_AGR_MACHINERY_AVAILABILITY%28~%29 | F12: https://stat.gov.ua/uk/explorer?urn=SSSU%3ADF_AREA_HARVESTS_CROP_YIELD_A%28~%29 | G12: 2070 | H12: =IF(G12="",D12,100*B12/G12) -> 9.5652174 | I12: https://stat.gov.ua/uk/explorer?urn=SSSU%3ADF_STOCKBREEDING_FODDER_A%28~%29
A13: AUTO_REG_CLIMATE | B13: 354 | C13: 30201 | D13: =100*B13/C13 -> 1.1721466 | E13: https://stat.gov.ua/uk/explorer?urn=SSSU%3ADF_AGR_MACHINERY_AVAILABILITY%28~%29 | F13: https://stat.gov.ua/uk/explorer?urn=SSSU%3ADF_AREA_HARVESTS_CROP_YIELD_A%28~%29 | G13: 2070 | H13: =IF(G13="",D13,100*B13/G13) -> 17.101449 | I13: https://stat.gov.ua/uk/explorer?urn=SSSU%3ADF_STOCKBREEDING_FODDER_A%28~%29

Sheet Farm_results
A1: Farm level: shares, ratios to the EU and partial layer scores
A3: Technology | B3: Ukraine 2025* | C3: EU-27 all | D3: EU-27 large | E3: Germany | F3: Poland | G3: Hungary | H3: Romania | I3: Czechia | J3: Slovakia | K3: Lithuania | L3: Latvia | M3: Estonia | N3: Bulgaria | O3: UA / EU-27 all | P3: UA / EU-27 large
A4: ROBOTICS | B4: =Farm_UA_data!$D$4 -> 3.9502003 | C4: =Farm_EU_data!$AE$5 -> 6.79 | D4: =Farm_EU_data!$AE$19 -> 31.3 | E4: =Farm_EU_data!$I$5 -> 18.26 | F4: =Farm_EU_data!$Y$5 -> 1.34 | G4: =Farm_EU_data!$Q$5 -> 2.62 | H4: =Farm_EU_data!$AA$5 -> 3.26 | I4: =Farm_EU_data!$H$5 -> 3.41 | J4: =Farm_EU_data!$AD$5 -> 1.31 | K4: =Farm_EU_data!$T$5 -> 0.46 | L4: =Farm_EU_data!$V$5 -> 4.68 | M4: =Farm_EU_data!$K$5 -> 8.03 | N4: =Farm_EU_data!$F$5 -> 0.56 | O4: =B4/C4 -> 0.58176735 | P4: =Farm_UA_data!$H$4/D4 -> 0.12620448
A5: MAC_ROB_PPP | B5: =Farm_UA_data!$D$5 -> 3.0164564 | C5: =Farm_EU_data!$AE$6 -> 1.76 | D5: =Farm_EU_data!$AE$20 -> 16.55 | E5: =Farm_EU_data!$I$6 -> 3.27 | F5: =Farm_EU_data!$Y$6 -> 0.22 | G5: =Farm_EU_data!$Q$6 -> 1.01 | H5: =Farm_EU_data!$AA$6 -> 0.14 | I5: =Farm_EU_data!$H$6 -> 0.86 | J5: =Farm_EU_data!$AD$6 -> 0.59 | K5: =Farm_EU_data!$T$6 -> 0.05 | L5: =Farm_EU_data!$V$6 -> 2.72 | M5: =Farm_EU_data!$K$6 -> 5.04 | N5: =Farm_EU_data!$F$6 -> 0.26 | O5: =B5/C5 -> 1.7138957 | P5: =Farm_UA_data!$H$5/D5 -> 0.18226323
A6: BAND_SPRAY_PPP | B6: =Farm_UA_data!$D$6 -> 1.3906824 | C6: =Farm_EU_data!$AE$7 -> 4.21 | D6: =Farm_EU_data!$AE$21 -> 8.07 | E6: =Farm_EU_data!$I$7 -> 7.7 | F6: =Farm_EU_data!$Y$7 -> 12.66 | G6: =Farm_EU_data!$Q$7 -> 3.34 | H6: =Farm_EU_data!$AA$7 -> 0.45 | I6: =Farm_EU_data!$H$7 -> 0.76 | J6: =Farm_EU_data!$AD$7 -> 0.18 | K6: =Farm_EU_data!$T$7 -> 0.43 | L6: =Farm_EU_data!$V$7 -> 1.39 | M6: =Farm_EU_data!$K$7 -> 4.75 | N6: =Farm_EU_data!$F$7 -> 0.29 | O6: =B6/C6 -> 0.33032837 | P6: =Farm_UA_data!$H$6/D6 -> 0.17232744
A7: VAR_RATE_TECH | B7: =Farm_UA_data!$D$7 -> 1.2946591 | C7: =Farm_EU_data!$AE$8 -> 5.32 | D7: =Farm_EU_data!$AE$22 -> 16.74 | E7: =Farm_EU_data!$I$8 -> 18.59 | F7: =Farm_EU_data!$Y$8 -> 13.69 | G7: =Farm_EU_data!$Q$8 -> 5.8 | H7: =Farm_EU_data!$AA$8 -> 0.78 | I7: =Farm_EU_data!$H$8 -> 3.36 | J7: =Farm_EU_data!$AD$8 -> 0.71 | K7: =Farm_EU_data!$T$8 -> 0.87 | L7: =Farm_EU_data!$V$8 -> 4.08 | M7: =Farm_EU_data!$K$8 -> 9.6 | N7: =Farm_EU_data!$F$8 -> 0.9 | O7: =B7/C7 -> 0.24335698 | P7: =Farm_UA_data!$H$7/D7 -> 0.077339254
A8: PREC_MON_CROPS | B8: =Farm_UA_data!$D$8 -> 2.9403 | C8: =Farm_EU_data!$AE$9 -> 3.23 | D8: =Farm_EU_data!$AE$23 -> 18.73 | E8: =Farm_EU_data!$I$9 -> 20.96 | F8: =Farm_EU_data!$Y$9 -> 2.82 | G8: =Farm_EU_data!$Q$9 -> 5.32 | H8: =Farm_EU_data!$AA$9 -> 0.37 | I8: =Farm_EU_data!$H$9 -> 1.77 | J8: =Farm_EU_data!$AD$9 -> 0.41 | K8: =Farm_EU_data!$T$9 -> 0.82 | L8: =Farm_EU_data!$V$9 -> 1.09 | M8: =Farm_EU_data!$K$9 -> 4.66 | N8: =Farm_EU_data!$F$9 -> 0.43 | O8: =B8/C8 -> 0.91030959 | P8: =Farm_UA_data!$H$8/D8 -> 0.15698345
A9: SOIL_ANALYSIS | B9: =Farm_UA_data!$D$9 -> 1.1555909 | C9: =Farm_EU_data!$AE$10 -> 11.35 | D9: =Farm_EU_data!$AE$24 -> 45.73 | E9: =Farm_EU_data!$I$10 -> 37.79 | F9: =Farm_EU_data!$Y$10 -> 12.31 | G9: =Farm_EU_data!$Q$10 -> 5.59 | H9: =Farm_EU_data!$AA$10 -> 0.3 | I9: =Farm_EU_data!$H$10 -> 1.34 | J9: =Farm_EU_data!$AD$10 -> 0.65 | K9: =Farm_EU_data!$T$10 -> 2.37 | L9: =Farm_EU_data!$V$10 -> 5.47 | M9: =Farm_EU_data!$K$10 -> 29.75 | N9: =Farm_EU_data!$F$10 -> 1.59 | O9: =B9/C9 -> 0.10181417 | P9: =Farm_UA_data!$H$9/D9 -> 0.025269864
A10: AUTO_FEED_SYS | B10: =Farm_UA_data!$D$10 -> 1.2151915 | C10: =Farm_EU_data!$AE$11 -> 2.44 | D10: =Farm_EU_data!$AE$25 -> 37.24 | E10: =Farm_EU_data!$I$11 -> 12.01 | F10: =Farm_EU_data!$Y$11 -> 1.98 | G10: =Farm_EU_data!$Q$11 -> 1.5 | H10: =Farm_EU_data!$AA$11 -> 0.37 | I10: =Farm_EU_data!$H$11 -> 1.69 | J10: =Farm_EU_data!$AD$11 -> 0.63 | K10: =Farm_EU_data!$T$11 -> 0.19 | L10: =Farm_EU_data!$V$11 -> 0.29 | M10: =Farm_EU_data!$K$11 -> 2.05 | N10: =Farm_EU_data!$F$11 -> 0.36 | O10: =B10/C10 -> 0.49802932 | P10: =Farm_UA_data!$H$10/D10 -> 0.4760867
A11: MILK_ROBOTS | B11: =Farm_UA_data!$D$11 -> 0.245025 | C11: =Farm_EU_data!$AE$12 -> 1.96 | D11: =Farm_EU_data!$AE$26 -> 14.6 | E11: =Farm_EU_data!$I$12 -> 3.46 | F11: =Farm_EU_data!$Y$12 -> 0.06 | G11: =Farm_EU_data!$Q$12 -> 0.23 | H11: =Farm_EU_data!$AA$12 -> 2.87 | I11: =Farm_EU_data!$H$12 -> 0.75 | J11: =Farm_EU_data!$AD$12 -> 0.03 | K11: =Farm_EU_data!$T$12 -> 0.1 | L11: =Farm_EU_data!$V$12 -> 0.53 | M11: =Farm_EU_data!$K$12 -> 0.75 | N11: =Farm_EU_data!$F$12 -> 0.01 | O11: =B11/C11 -> 0.12501275 | P11: =Farm_UA_data!$H$11/D11 -> 0.24485474
A12: MON_ANIMALS | B12: =Farm_UA_data!$D$12 -> 0.65560743 | C12: =Farm_EU_data!$AE$13 -> 4.69 | D12: =Farm_EU_data!$AE$27 -> 49.07 | E12: =Farm_EU_data!$I$13 -> 11.02 | F12: =Farm_EU_data!$Y$13 -> 3.21 | G12: =Farm_EU_data!$Q$13 -> 2.58 | H12: =Farm_EU_data!$AA$13 -> 0.38 | I12: =Farm_EU_data!$H$13 -> 2.71 | J12: =Farm_EU_data!$AD$13 -> 0.68 | K12: =Farm_EU_data!$T$13 -> 1.21 | L12: =Farm_EU_data!$V$13 -> 1.78 | M12: =Farm_EU_data!$K$13 -> 9.62 | N12: =Farm_EU_data!$F$13 -> 3.08 | O12: =B12/C12 -> 0.13978836 | P12: =Farm_UA_data!$H$12/D12 -> 0.19493005
A13: AUTO_REG_CLIMATE | B13: =Farm_UA_data!$D$13 -> 1.1721466 | C13: =Farm_EU_data!$AE$14 -> 2.51 | D13: =Farm_EU_data!$AE$28 -> 38.52 | E13: =Farm_EU_data!$I$14 -> 11.67 | F13: =Farm_EU_data!$Y$14 -> 2.13 | G13: =Farm_EU_data!$Q$14 -> 0.85 | H13: =Farm_EU_data!$AA$14 -> 0.17 | I13: =Farm_EU_data!$H$14 -> 2.14 | J13: =Farm_EU_data!$AD$14 -> 0.46 | K13: =Farm_EU_data!$T$14 -> 0.17 | L13: =Farm_EU_data!$V$14 -> 0.43 | M13: =Farm_EU_data!$K$14 -> 1.87 | N13: =Farm_EU_data!$F$14 -> 0.53 | O13: =B13/C13 -> 0.46699068 | P13: =Farm_UA_data!$H$13/D13 -> 0.44396286
A15: Median ratio | O15: =(SMALL(O4:O13,5)+SMALL(O4:O13,6))/2 -> 0.39865953 | P15: =(SMALL(P4:P13,5)+SMALL(P4:P13,6))/2 -> 0.17729533
A18: Partial layer scores, EU basis: all holdings (DM = MIN(1, P / P_leader))
A19: Unit | B19: ROBOTICS | C19: MAC_ROB_PPP | D19: BAND_SPRAY_PPP | E19: VAR_RATE_TECH | F19: PREC_MON_CROPS | G19: SOIL_ANALYSIS | H19: AUTO_FEED_SYS | I19: MILK_ROBOTS | J19: MON_ANIMALS | K19: AUTO_REG_CLIMATE | L19: DM_C | M19: DM_L3 | N19: DM_L3 crop | O19: DM_L3 livestock
A20: EU27_2020 | B20: =MIN(1,Farm_EU_data!$AE$5/Farm_EU_data!$AF$5) -> 0.19388921 | C20: =MIN(1,Farm_EU_data!$AE$6/Farm_EU_data!$AF$6) -> 0.08956743 | D20: =MIN(1,Farm_EU_data!$AE$7/Farm_EU_data!$AF$7) -> 0.33254344 | E20: =MIN(1,Farm_EU_data!$AE$8/Farm_EU_data!$AF$8) -> 0.28617536 | F20: =MIN(1,Farm_EU_data!$AE$9/Farm_EU_data!$AF$9) -> 0.15410305 | G20: =MIN(1,Farm_EU_data!$AE$10/Farm_EU_data!$AF$10) -> 0.17893741 | H20: =MIN(1,Farm_EU_data!$AE$11/Farm_EU_data!$AF$11) -> 0.16084377 | I20: =MIN(1,Farm_EU_data!$AE$12/Farm_EU_data!$AF$12) -> 0.15947925 | J20: =MIN(1,Farm_EU_data!$AE$13/Farm_EU_data!$AF$13) -> 0.1713555 | K20: =MIN(1,Farm_EU_data!$AE$14/Farm_EU_data!$AF$14) -> 0.1584596 | L20: =B20 -> 0.19388921 | M20: =AVERAGE(C20:K20) -> 0.18794054 | N20: =AVERAGE(C20:G20) -> 0.20826534 | O20: =AVERAGE(H20:K20) -> 0.16253453
A21: DE | B21: =MIN(1,Farm_EU_data!$I$5/Farm_EU_data!$AF$5) -> 0.52141633 | C21: =MIN(1,Farm_EU_data!$I$6/Farm_EU_data!$AF$6) -> 0.16641221 | D21: =MIN(1,Farm_EU_data!$I$7/Farm_EU_data!$AF$7) -> 0.60821485 | E21: =MIN(1,Farm_EU_data!$I$8/Farm_EU_data!$AF$8) -> 1 | F21: =MIN(1,Farm_EU_data!$I$9/Farm_EU_data!$AF$9) -> 1 | G21: =MIN(1,Farm_EU_data!$I$10/Farm_EU_data!$AF$10) -> 0.59577487 | H21: =MIN(1,Farm_EU_data!$I$11/Farm_EU_data!$AF$11) -> 0.79169413 | I21: =MIN(1,Farm_EU_data!$I$12/Farm_EU_data!$AF$12) -> 0.2815297 | J21: =MIN(1,Farm_EU_data!$I$13/Farm_EU_data!$AF$13) -> 0.40263062 | K21: =MIN(1,Farm_EU_data!$I$14/Farm_EU_data!$AF$14) -> 0.73674242 | L21: =B21 -> 0.52141633 | M21: =AVERAGE(C21:K21) -> 0.6203332 | N21: =AVERAGE(C21:G21) -> 0.67408039 | O21: =AVERAGE(H21:K21) -> 0.55314922
A22: PL | B22: =MIN(1,Farm_EU_data!$Y$5/Farm_EU_data!$AF$5) -> 0.038263849 | C22: =MIN(1,Farm_EU_data!$Y$6/Farm_EU_data!$AF$6) -> 0.011195929 | D22: =MIN(1,Farm_EU_data!$Y$7/Farm_EU_data!$AF$7) -> 1 | E22: =MIN(1,Farm_EU_data!$Y$8/Farm_EU_data!$AF$8) -> 0.73641743 | F22: =MIN(1,Farm_EU_data!$Y$9/Farm_EU_data!$AF$9) -> 0.13454198 | G22: =MIN(1,Farm_EU_data!$Y$10/Farm_EU_data!$AF$10) -> 0.19407221 | H22: =MIN(1,Farm_EU_data!$Y$11/Farm_EU_data!$AF$11) -> 0.13052076 | I22: =MIN(1,Farm_EU_data!$Y$12/Farm_EU_data!$AF$12) -> 0.0048820179 | J22: =MIN(1,Farm_EU_data!$Y$13/Farm_EU_data!$AF$13) -> 0.1172817 | K22: =MIN(1,Farm_EU_data!$Y$14/Farm_EU_data!$AF$14) -> 0.1344697 | L22: =B22 -> 0.038263849 | M22: =AVERAGE(C22:K22) -> 0.27370908 | N22: =AVERAGE(C22:G22) -> 0.41524551 | O22: =AVERAGE(H22:K22) -> 0.096788544
A23: HU | B23: =MIN(1,Farm_EU_data!$Q$5/Farm_EU_data!$AF$5) -> 0.074814392 | C23: =MIN(1,Farm_EU_data!$Q$6/Farm_EU_data!$AF$6) -> 0.051399491 | D23: =MIN(1,Farm_EU_data!$Q$7/Farm_EU_data!$AF$7) -> 0.26382306 | E23: =MIN(1,Farm_EU_data!$Q$8/Farm_EU_data!$AF$8) -> 0.3119957 | F23: =MIN(1,Farm_EU_data!$Q$9/Farm_EU_data!$AF$9) -> 0.25381679 | G23: =MIN(1,Farm_EU_data!$Q$10/Farm_EU_data!$AF$10) -> 0.088128646 | H23: =MIN(1,Farm_EU_data!$Q$11/Farm_EU_data!$AF$11) -> 0.098879367 | I23: =MIN(1,Farm_EU_data!$Q$12/Farm_EU_data!$AF$12) -> 0.018714402 | J23: =MIN(1,Farm_EU_data!$Q$13/Farm_EU_data!$AF$13) -> 0.094263792 | K23: =MIN(1,Farm_EU_data!$Q$14/Farm_EU_data!$AF$14) -> 0.053661616 | L23: =B23 -> 0.074814392 | M23: =AVERAGE(C23:K23) -> 0.13718699 | N23: =AVERAGE(C23:G23) -> 0.19383274 | O23: =AVERAGE(H23:K23) -> 0.066379794
A24: RO | B24: =MIN(1,Farm_EU_data!$AA$5/Farm_EU_data!$AF$5) -> 0.093089663 | C24: =MIN(1,Farm_EU_data!$AA$6/Farm_EU_data!$AF$6) -> 0.0071246819 | D24: =MIN(1,Farm_EU_data!$AA$7/Farm_EU_data!$AF$7) -> 0.035545024 | E24: =MIN(1,Farm_EU_data!$AA$8/Farm_EU_data!$AF$8) -> 0.041958042 | F24: =MIN(1,Farm_EU_data!$AA$9/Farm_EU_data!$AF$9) -> 0.017652672 | G24: =MIN(1,Farm_EU_data!$AA$10/Farm_EU_data!$AF$10) -> 0.0047296232 | H24: =MIN(1,Farm_EU_data!$AA$11/Farm_EU_data!$AF$11) -> 0.024390244 | I24: =MIN(1,Farm_EU_data!$AA$12/Farm_EU_data!$AF$12) -> 0.23352319 | J24: =MIN(1,Farm_EU_data!$AA$13/Farm_EU_data!$AF$13) -> 0.013883814 | K24: =MIN(1,Farm_EU_data!$AA$14/Farm_EU_data!$AF$14) -> 0.010732323 | L24: =B24 -> 0.093089663 | M24: =AVERAGE(C24:K24) -> 0.043282179 | N24: =AVERAGE(C24:G24) -> 0.021402009 | O24: =AVERAGE(H24:K24) -> 0.070632393
A25: CZ | B25: =MIN(1,Farm_EU_data!$H$5/Farm_EU_data!$AF$5) -> 0.09737293 | C25: =MIN(1,Farm_EU_data!$H$6/Farm_EU_data!$AF$6) -> 0.043765903 | D25: =MIN(1,Farm_EU_data!$H$7/Farm_EU_data!$AF$7) -> 0.060031596 | E25: =MIN(1,Farm_EU_data!$H$8/Farm_EU_data!$AF$8) -> 0.18074233 | F25: =MIN(1,Farm_EU_data!$H$9/Farm_EU_data!$AF$9) -> 0.084446565 | G25: =MIN(1,Farm_EU_data!$H$10/Farm_EU_data!$AF$10) -> 0.02112565 | H25: =MIN(1,Farm_EU_data!$H$11/Farm_EU_data!$AF$11) -> 0.11140409 | I25: =MIN(1,Farm_EU_data!$H$12/Farm_EU_data!$AF$12) -> 0.061025224 | J25: =MIN(1,Farm_EU_data!$H$13/Farm_EU_data!$AF$13) -> 0.099013518 | K25: =MIN(1,Farm_EU_data!$H$14/Farm_EU_data!$AF$14) -> 0.13510101 | L25: =B25 -> 0.09737293 | M25: =AVERAGE(C25:K25) -> 0.088517321 | N25: =AVERAGE(C25:G25) -> 0.07802241 | O25: =AVERAGE(H25:K25) -> 0.10163596
A26: SK | B26: =MIN(1,Farm_EU_data!$AD$5/Farm_EU_data!$AF$5) -> 0.037407196 | C26: =MIN(1,Farm_EU_data!$AD$6/Farm_EU_data!$AF$6) -> 0.030025445 | D26: =MIN(1,Farm_EU_data!$AD$7/Farm_EU_data!$AF$7) -> 0.014218009 | E26: =MIN(1,Farm_EU_data!$AD$8/Farm_EU_data!$AF$8) -> 0.038192577 | F26: =MIN(1,Farm_EU_data!$AD$9/Farm_EU_data!$AF$9) -> 0.019561069 | G26: =MIN(1,Farm_EU_data!$AD$10/Farm_EU_data!$AF$10) -> 0.010247517 | H26: =MIN(1,Farm_EU_data!$AD$11/Farm_EU_data!$AF$11) -> 0.041529334 | I26: =MIN(1,Farm_EU_data!$AD$12/Farm_EU_data!$AF$12) -> 0.002441009 | J26: =MIN(1,Farm_EU_data!$AD$13/Farm_EU_data!$AF$13) -> 0.02484472 | K26: =MIN(1,Farm_EU_data!$AD$14/Farm_EU_data!$AF$14) -> 0.029040404 | L26: =B26 -> 0.037407196 | M26: =AVERAGE(C26:K26) -> 0.023344454 | N26: =AVERAGE(C26:G26) -> 0.022448923 | O26: =AVERAGE(H26:K26) -> 0.024463867
A27: LT | B27: =MIN(1,Farm_EU_data!$T$5/Farm_EU_data!$AF$5) -> 0.013135351 | C27: =MIN(1,Farm_EU_data!$T$6/Farm_EU_data!$AF$6) -> 0.0025445293 | D27: =MIN(1,Farm_EU_data!$T$7/Farm_EU_data!$AF$7) -> 0.033965245 | E27: =MIN(1,Farm_EU_data!$T$8/Farm_EU_data!$AF$8) -> 0.046799354 | F27: =MIN(1,Farm_EU_data!$T$9/Farm_EU_data!$AF$9) -> 0.039122137 | G27: =MIN(1,Farm_EU_data!$T$10/Farm_EU_data!$AF$10) -> 0.037364023 | H27: =MIN(1,Farm_EU_data!$T$11/Farm_EU_data!$AF$11) -> 0.01252472 | I27: =MIN(1,Farm_EU_data!$T$12/Farm_EU_data!$AF$12) -> 0.0081366965 | J27: =MIN(1,Farm_EU_data!$T$13/Farm_EU_data!$AF$13) -> 0.044208988 | K27: =MIN(1,Farm_EU_data!$T$14/Farm_EU_data!$AF$14) -> 0.010732323 | L27: =B27 -> 0.013135351 | M27: =AVERAGE(C27:K27) -> 0.026155335 | N27: =AVERAGE(C27:G27) -> 0.031959058 | O27: =AVERAGE(H27:K27) -> 0.018900682
A28: LV | B28: =MIN(1,Farm_EU_data!$V$5/Farm_EU_data!$AF$5) -> 0.13363792 | C28: =MIN(1,Farm_EU_data!$V$6/Farm_EU_data!$AF$6) -> 0.13842239 | D28: =MIN(1,Farm_EU_data!$V$7/Farm_EU_data!$AF$7) -> 0.10979463 | E28: =MIN(1,Farm_EU_data!$V$8/Farm_EU_data!$AF$8) -> 0.21947283 | F28: =MIN(1,Farm_EU_data!$V$9/Farm_EU_data!$AF$9) -> 0.052003817 | G28: =MIN(1,Farm_EU_data!$V$10/Farm_EU_data!$AF$10) -> 0.086236796 | H28: =MIN(1,Farm_EU_data!$V$11/Farm_EU_data!$AF$11) -> 0.019116678 | I28: =MIN(1,Farm_EU_data!$V$12/Farm_EU_data!$AF$12) -> 0.043124491 | J28: =MIN(1,Farm_EU_data!$V$13/Farm_EU_data!$AF$13) -> 0.06503471 | K28: =MIN(1,Farm_EU_data!$V$14/Farm_EU_data!$AF$14) -> 0.027146465 | L28: =B28 -> 0.13363792 | M28: =AVERAGE(C28:K28) -> 0.084483646 | N28: =AVERAGE(C28:G28) -> 0.12118609 | O28: =AVERAGE(H28:K28) -> 0.038605586
A29: EE | B29: =MIN(1,Farm_EU_data!$K$5/Farm_EU_data!$AF$5) -> 0.22929754 | C29: =MIN(1,Farm_EU_data!$K$6/Farm_EU_data!$AF$6) -> 0.25648855 | D29: =MIN(1,Farm_EU_data!$K$7/Farm_EU_data!$AF$7) -> 0.37519747 | E29: =MIN(1,Farm_EU_data!$K$8/Farm_EU_data!$AF$8) -> 0.51640667 | F29: =MIN(1,Farm_EU_data!$K$9/Farm_EU_data!$AF$9) -> 0.22232824 | G29: =MIN(1,Farm_EU_data!$K$10/Farm_EU_data!$AF$10) -> 0.46902097 | H29: =MIN(1,Farm_EU_data!$K$11/Farm_EU_data!$AF$11) -> 0.13513514 | I29: =MIN(1,Farm_EU_data!$K$12/Farm_EU_data!$AF$12) -> 0.061025224 | J29: =MIN(1,Farm_EU_data!$K$13/Farm_EU_data!$AF$13) -> 0.35147972 | K29: =MIN(1,Farm_EU_data!$K$14/Farm_EU_data!$AF$14) -> 0.11805556 | L29: =B29 -> 0.22929754 | M29: =AVERAGE(C29:K29) -> 0.27834862 | N29: =AVERAGE(C29:G29) -> 0.36788838 | O29: =AVERAGE(H29:K29) -> 0.16642391
A30: BG | B30: =MIN(1,Farm_EU_data!$F$5/Farm_EU_data!$AF$5) -> 0.015990862 | C30: =MIN(1,Farm_EU_data!$F$6/Farm_EU_data!$AF$6) -> 0.013231552 | D30: =MIN(1,Farm_EU_data!$F$7/Farm_EU_data!$AF$7) -> 0.022906793 | E30: =MIN(1,Farm_EU_data!$F$8/Farm_EU_data!$AF$8) -> 0.048413125 | F30: =MIN(1,Farm_EU_data!$F$9/Farm_EU_data!$AF$9) -> 0.020515267 | G30: =MIN(1,Farm_EU_data!$F$10/Farm_EU_data!$AF$10) -> 0.025067003 | H30: =MIN(1,Farm_EU_data!$F$11/Farm_EU_data!$AF$11) -> 0.023731048 | I30: =MIN(1,Farm_EU_data!$F$12/Farm_EU_data!$AF$12) -> 0.00081366965 | J30: =MIN(1,Farm_EU_data!$F$13/Farm_EU_data!$AF$13) -> 0.11253197 | K30: =MIN(1,Farm_EU_data!$F$14/Farm_EU_data!$AF$14) -> 0.033459596 | L30: =B30 -> 0.015990862 | M30: =AVERAGE(C30:K30) -> 0.03340778 | N30: =AVERAGE(C30:G30) -> 0.026026748 | O30: =AVERAGE(H30:K30) -> 0.042634071
A31: UA | B31: =MIN(1,Farm_UA_data!$D$4/Farm_EU_data!$AF$5) -> 0.11279841 | C31: =MIN(1,Farm_UA_data!$D$5/Farm_EU_data!$AF$6) -> 0.15350923 | D31: =MIN(1,Farm_UA_data!$D$6/Farm_EU_data!$AF$7) -> 0.10984853 | E31: =MIN(1,Farm_UA_data!$D$7/Farm_EU_data!$AF$8) -> 0.069642771 | F31: =MIN(1,Farm_UA_data!$D$8/Farm_EU_data!$AF$9) -> 0.14028149 | G31: =MIN(1,Farm_UA_data!$D$9/Farm_EU_data!$AF$10) -> 0.018218365 | H31: =MIN(1,Farm_UA_data!$D$10/Farm_EU_data!$AF$11) -> 0.080104914 | I31: =MIN(1,Farm_UA_data!$D$11/Farm_EU_data!$AF$12) -> 0.019936941 | J31: =MIN(1,Farm_UA_data!$D$12/Farm_EU_data!$AF$13) -> 0.023953505 | K31: =MIN(1,Farm_UA_data!$D$13/Farm_EU_data!$AF$14) -> 0.073999155 | L31: =B31 -> 0.11279841 | M31: =AVERAGE(C31:K31) -> 0.076610545 | N31: =AVERAGE(C31:G31) -> 0.098300078 | O31: =AVERAGE(H31:K31) -> 0.049498629
A36: Partial layer scores, EU basis: large holdings (DM = MIN(1, P / P_leader))
A37: Unit | B37: ROBOTICS | C37: MAC_ROB_PPP | D37: BAND_SPRAY_PPP | E37: VAR_RATE_TECH | F37: PREC_MON_CROPS | G37: SOIL_ANALYSIS | H37: AUTO_FEED_SYS | I37: MILK_ROBOTS | J37: MON_ANIMALS | K37: AUTO_REG_CLIMATE | L37: DM_C | M37: DM_L3 | N37: DM_L3 crop | O37: DM_L3 livestock
A38: EU27_2020 | B38: =MIN(1,Farm_EU_data!$AE$19/Farm_EU_data!$AF$19) -> 0.56785196 | C38: =MIN(1,Farm_EU_data!$AE$20/Farm_EU_data!$AF$20) -> 0.3230529 | D38: =MIN(1,Farm_EU_data!$AE$21/Farm_EU_data!$AF$21) -> 0.34428328 | E38: =MIN(1,Farm_EU_data!$AE$22/Farm_EU_data!$AF$22) -> 0.36582168 | F38: =MIN(1,Farm_EU_data!$AE$23/Farm_EU_data!$AF$23) -> 0.36899133 | G38: =MIN(1,Farm_EU_data!$AE$24/Farm_EU_data!$AF$24) -> 0.52690402 | H38: =MIN(1,Farm_EU_data!$AE$25/Farm_EU_data!$AF$25) -> 0.49448944 | I38: =MIN(1,Farm_EU_data!$AE$26/Farm_EU_data!$AF$26) -> 0.35299807 | J38: =MIN(1,Farm_EU_data!$AE$27/Farm_EU_data!$AF$27) -> 0.6515735 | K38: =MIN(1,Farm_EU_data!$AE$28/Farm_EU_data!$AF$28) -> 0.51305274 | L38: =B38 -> 0.56785196 | M38: =AVERAGE(C38:K38) -> 0.43790744 | N38: =AVERAGE(C38:G38) -> 0.38581064 | O38: =AVERAGE(H38:K38) -> 0.50302844
A39: DE | B39: =MIN(1,Farm_EU_data!$I$19/Farm_EU_data!$AF$19) -> 0.76306241 | C39: =MIN(1,Farm_EU_data!$I$20/Farm_EU_data!$AF$20) -> 0.19519813 | D39: =MIN(1,Farm_EU_data!$I$21/Farm_EU_data!$AF$21) -> 0.52943686 | E39: =MIN(1,Farm_EU_data!$I$22/Farm_EU_data!$AF$22) -> 1 | F39: =MIN(1,Farm_EU_data!$I$23/Farm_EU_data!$AF$23) -> 1 | G39: =MIN(1,Farm_EU_data!$I$24/Farm_EU_data!$AF$24) -> 0.76356723 | H39: =MIN(1,Farm_EU_data!$I$25/Farm_EU_data!$AF$25) -> 0.72885407 | I39: =MIN(1,Farm_EU_data!$I$26/Farm_EU_data!$AF$26) -> 0.40812379 | J39: =MIN(1,Farm_EU_data!$I$27/Farm_EU_data!$AF$27) -> 0.53830833 | K39: =MIN(1,Farm_EU_data!$I$28/Farm_EU_data!$AF$28) -> 0.67954182 | L39: =B39 -> 0.76306241 | M39: =AVERAGE(C39:K39) -> 0.64922558 | N39: =AVERAGE(C39:G39) -> 0.69764044 | O39: =AVERAGE(H39:K39) -> 0.588707
A40: PL | B40: =MIN(1,Farm_EU_data!$Y$19/Farm_EU_data!$AF$19) -> 0.13080552 | C40: =MIN(1,Farm_EU_data!$Y$20/Farm_EU_data!$AF$20) -> 0.077298458 | D40: =MIN(1,Farm_EU_data!$Y$21/Farm_EU_data!$AF$21) -> 1 | E40: =MIN(1,Farm_EU_data!$Y$22/Farm_EU_data!$AF$22) -> 0.57386364 | F40: =MIN(1,Farm_EU_data!$Y$23/Farm_EU_data!$AF$23) -> 0.321513 | G40: =MIN(1,Farm_EU_data!$Y$24/Farm_EU_data!$AF$24) -> 0.53393248 | H40: =MIN(1,Farm_EU_data!$Y$25/Farm_EU_data!$AF$25) -> 0.79591024 | I40: =MIN(1,Farm_EU_data!$Y$26/Farm_EU_data!$AF$26) -> 0.10275629 | J40: =MIN(1,Farm_EU_data!$Y$27/Farm_EU_data!$AF$27) -> 0.62249369 | K40: =MIN(1,Farm_EU_data!$Y$28/Farm_EU_data!$AF$28) -> 0.7225626 | L40: =B40 -> 0.13080552 | M40: =AVERAGE(C40:K40) -> 0.52781449 | N40: =AVERAGE(C40:G40) -> 0.50132152 | O40: =AVERAGE(H40:K40) -> 0.5609307
A41: HU | B41: =MIN(1,Farm_EU_data!$Q$19/Farm_EU_data!$AF$19) -> 0.26904935 | C41: =MIN(1,Farm_EU_data!$Q$20/Farm_EU_data!$AF$20) -> 0.088034355 | D41: =MIN(1,Farm_EU_data!$Q$21/Farm_EU_data!$AF$21) -> 0.59513652 | E41: =MIN(1,Farm_EU_data!$Q$22/Farm_EU_data!$AF$22) -> 0.58697552 | F41: =MIN(1,Farm_EU_data!$Q$23/Farm_EU_data!$AF$23) -> 0.464342 | G41: =MIN(1,Farm_EU_data!$Q$24/Farm_EU_data!$AF$24) -> 0.30049545 | H41: =MIN(1,Farm_EU_data!$Q$25/Farm_EU_data!$AF$25) -> 0.54680653 | I41: =MIN(1,Farm_EU_data!$Q$26/Farm_EU_data!$AF$26) -> 0.10662476 | J41: =MIN(1,Farm_EU_data!$Q$27/Farm_EU_data!$AF$27) -> 0.67042889 | K41: =MIN(1,Farm_EU_data!$Q$28/Farm_EU_data!$AF$28) -> 0.46350559 | L41: =B41 -> 0.26904935 | M41: =AVERAGE(C41:K41) -> 0.42470551 | N41: =AVERAGE(C41:G41) -> 0.40699677 | O41: =AVERAGE(H41:K41) -> 0.44684144
A42: RO | B42: =MIN(1,Farm_EU_data!$AA$19/Farm_EU_data!$AF$19) -> 0.31240929 | C42: =MIN(1,Farm_EU_data!$AA$20/Farm_EU_data!$AF$20) -> 0.02498536 | D42: =MIN(1,Farm_EU_data!$AA$21/Farm_EU_data!$AF$21) -> 0.20989761 | E42: =MIN(1,Farm_EU_data!$AA$22/Farm_EU_data!$AF$22) -> 0.21634615 | F42: =MIN(1,Farm_EU_data!$AA$23/Farm_EU_data!$AF$23) -> 0.10066982 | G42: =MIN(1,Farm_EU_data!$AA$24/Farm_EU_data!$AF$24) -> 0.073625994 | H42: =MIN(1,Farm_EU_data!$AA$25/Farm_EU_data!$AF$25) -> 0.36675076 | I42: =MIN(1,Farm_EU_data!$AA$26/Farm_EU_data!$AF$26) -> 0.99008704 | J42: =MIN(1,Farm_EU_data!$AA$27/Farm_EU_data!$AF$27) -> 0.2465808 | K42: =MIN(1,Farm_EU_data!$AA$28/Farm_EU_data!$AF$28) -> 0.1965903 | L42: =B42 -> 0.31240929 | M42: =AVERAGE(C42:K42) -> 0.26950376 | N42: =AVERAGE(C42:G42) -> 0.12510499 | O42: =AVERAGE(H42:K42) -> 0.45000223
A43: CZ | B43: =MIN(1,Farm_EU_data!$H$19/Farm_EU_data!$AF$19) -> 0.26505806 | C43: =MIN(1,Farm_EU_data!$H$20/Farm_EU_data!$AF$20) -> 0.072613703 | D43: =MIN(1,Farm_EU_data!$H$21/Farm_EU_data!$AF$21) -> 0.13609215 | E43: =MIN(1,Farm_EU_data!$H$22/Farm_EU_data!$AF$22) -> 0.34047203 | F43: =MIN(1,Farm_EU_data!$H$23/Farm_EU_data!$AF$23) -> 0.16390859 | G43: =MIN(1,Farm_EU_data!$H$24/Farm_EU_data!$AF$24) -> 0.067288858 | H43: =MIN(1,Farm_EU_data!$H$25/Farm_EU_data!$AF$25) -> 0.27579339 | I43: =MIN(1,Farm_EU_data!$H$26/Farm_EU_data!$AF$26) -> 0.21034816 | J43: =MIN(1,Farm_EU_data!$H$27/Farm_EU_data!$AF$27) -> 0.47470455 | K43: =MIN(1,Farm_EU_data!$H$28/Farm_EU_data!$AF$28) -> 0.38612147 | L43: =B43 -> 0.26505806 | M43: =AVERAGE(C43:K43) -> 0.23637143 | N43: =AVERAGE(C43:G43) -> 0.15607507 | O43: =AVERAGE(H43:K43) -> 0.33674189
A44: SK | B44: =MIN(1,Farm_EU_data!$AD$19/Farm_EU_data!$AF$19) -> 0.13461538 | C44: =MIN(1,Farm_EU_data!$AD$20/Farm_EU_data!$AF$20) -> 0.068904939 | D44: =MIN(1,Farm_EU_data!$AD$21/Farm_EU_data!$AF$21) -> 0.050341297 | E44: =MIN(1,Farm_EU_data!$AD$22/Farm_EU_data!$AF$22) -> 0.094187063 | F44: =MIN(1,Farm_EU_data!$AD$23/Farm_EU_data!$AF$23) -> 0.046296296 | G44: =MIN(1,Farm_EU_data!$AD$24/Farm_EU_data!$AF$24) -> 0.036179283 | H44: =MIN(1,Farm_EU_data!$AD$25/Farm_EU_data!$AF$25) -> 0.14221219 | I44: =MIN(1,Farm_EU_data!$AD$26/Farm_EU_data!$AF$26) -> 0.02877176 | J44: =MIN(1,Farm_EU_data!$AD$27/Farm_EU_data!$AF$27) -> 0.14221219 | K44: =MIN(1,Farm_EU_data!$AD$28/Farm_EU_data!$AF$28) -> 0.11094832 | L44: =B44 -> 0.13461538 | M44: =AVERAGE(C44:K44) -> 0.080005927 | N44: =AVERAGE(C44:G44) -> 0.059181776 | O44: =AVERAGE(H44:K44) -> 0.10603612
A45: LT | B45: =MIN(1,Farm_EU_data!$T$19/Farm_EU_data!$AF$19) -> 0.092525399 | C45: =MIN(1,Farm_EU_data!$T$20/Farm_EU_data!$AF$20) -> 0.0099551044 | D45: =MIN(1,Farm_EU_data!$T$21/Farm_EU_data!$AF$21) -> 0.17235495 | E45: =MIN(1,Farm_EU_data!$T$22/Farm_EU_data!$AF$22) -> 0.19121503 | F45: =MIN(1,Farm_EU_data!$T$23/Farm_EU_data!$AF$23) -> 0.15248227 | G45: =MIN(1,Farm_EU_data!$T$24/Farm_EU_data!$AF$24) -> 0.1958751 | H45: =MIN(1,Farm_EU_data!$T$25/Farm_EU_data!$AF$25) -> 0.18722613 | I45: =MIN(1,Farm_EU_data!$T$26/Farm_EU_data!$AF$26) -> 0.18592843 | J45: =MIN(1,Farm_EU_data!$T$27/Farm_EU_data!$AF$27) -> 0.42557429 | K45: =MIN(1,Farm_EU_data!$T$28/Farm_EU_data!$AF$28) -> 0.1707512 | L45: =B45 -> 0.092525399 | M45: =AVERAGE(C45:K45) -> 0.18792917 | N45: =AVERAGE(C45:G45) -> 0.14437649 | O45: =AVERAGE(H45:K45) -> 0.24237001
A46: LV | B46: =MIN(1,Farm_EU_data!$V$19/Farm_EU_data!$AF$19) -> 0.74056604 | C46: =MIN(1,Farm_EU_data!$V$20/Farm_EU_data!$AF$20) -> 0.4165528 | D46: =MIN(1,Farm_EU_data!$V$21/Farm_EU_data!$AF$21) -> 0.40571672 | E46: =MIN(1,Farm_EU_data!$V$22/Farm_EU_data!$AF$22) -> 0.64597902 | F46: =MIN(1,Farm_EU_data!$V$23/Farm_EU_data!$AF$23) -> 0.16706068 | G46: =MIN(1,Farm_EU_data!$V$24/Farm_EU_data!$AF$24) -> 0.32872451 | H46: =MIN(1,Farm_EU_data!$V$25/Farm_EU_data!$AF$25) -> 0.16305935 | I46: =MIN(1,Farm_EU_data!$V$26/Farm_EU_data!$AF$26) -> 0.46663443 | J46: =MIN(1,Farm_EU_data!$V$27/Farm_EU_data!$AF$27) -> 0.44257071 | K46: =MIN(1,Farm_EU_data!$V$28/Farm_EU_data!$AF$28) -> 0.210309 | L46: =B46 -> 0.74056604 | M46: =AVERAGE(C46:K46) -> 0.36073414 | N46: =AVERAGE(C46:G46) -> 0.39280675 | O46: =AVERAGE(H46:K46) -> 0.32064337
A47: EE | B47: =MIN(1,Farm_EU_data!$K$19/Farm_EU_data!$AF$19) -> 0.62753991 | C47: =MIN(1,Farm_EU_data!$K$20/Farm_EU_data!$AF$20) -> 0.35662698 | D47: =MIN(1,Farm_EU_data!$K$21/Farm_EU_data!$AF$21) -> 0.57423208 | E47: =MIN(1,Farm_EU_data!$K$22/Farm_EU_data!$AF$22) -> 0.70388986 | F47: =MIN(1,Farm_EU_data!$K$23/Farm_EU_data!$AF$23) -> 0.32210402 | G47: =MIN(1,Farm_EU_data!$K$24/Farm_EU_data!$AF$24) -> 0.84203249 | H47: =MIN(1,Farm_EU_data!$K$25/Farm_EU_data!$AF$25) -> 0.50418271 | I47: =MIN(1,Farm_EU_data!$K$26/Farm_EU_data!$AF$26) -> 0.42843327 | J47: =MIN(1,Farm_EU_data!$K$27/Farm_EU_data!$AF$27) -> 0.87398752 | K47: =MIN(1,Farm_EU_data!$K$28/Farm_EU_data!$AF$28) -> 0.50572722 | L47: =B47 -> 0.62753991 | M47: =AVERAGE(C47:K47) -> 0.56791291 | N47: =AVERAGE(C47:G47) -> 0.55977709 | O47: =AVERAGE(H47:K47) -> 0.57808268
A48: BG | B48: =MIN(1,Farm_EU_data!$F$19/Farm_EU_data!$AF$19) -> 0.093432511 | C48: =MIN(1,Farm_EU_data!$F$20/Farm_EU_data!$AF$20) -> 0.044309975 | D48: =MIN(1,Farm_EU_data!$F$21/Farm_EU_data!$AF$21) -> 0.073805461 | E48: =MIN(1,Farm_EU_data!$F$22/Farm_EU_data!$AF$22) -> 0.15734266 | F48: =MIN(1,Farm_EU_data!$F$23/Farm_EU_data!$AF$23) -> 0.041962175 | G48: =MIN(1,Farm_EU_data!$F$24/Farm_EU_data!$AF$24) -> 0.072243346 | H48: =MIN(1,Farm_EU_data!$F$25/Farm_EU_data!$AF$25) -> 0.20515204 | I48: =MIN(1,Farm_EU_data!$F$26/Farm_EU_data!$AF$26) -> 0.019584139 | J48: =MIN(1,Farm_EU_data!$F$27/Farm_EU_data!$AF$27) -> 0.51812508 | K48: =MIN(1,Farm_EU_data!$F$28/Farm_EU_data!$AF$28) -> 0.25985615 | L48: =B48 -> 0.093432511 | M48: =AVERAGE(C48:K48) -> 0.154709 | N48: =AVERAGE(C48:G48) -> 0.077932723 | O48: =AVERAGE(H48:K48) -> 0.25067935
...

Sheet Processing_data
A1: Food processing (NACE C10-C12), enterprises 10+, % of enterprises: Eurostat and Derzhstat values
A3: Pair | B3: Component | C3: Eurostat dataset | D3: Eurostat indicator | E3: Year EU | F3: Year UA | G3: AT | H3: BE | I3: BG | J3: CY | K3: CZ | L3: DE | M3: DK | N3: EE | O3: EL | P3: ES | Q3: FI | R3: FR | S3: HR | T3: HU | U3: IE | V3: IT | W3: LT | X3: LU | Y3: LV | Z3: MT | AA3: NL | AB3: PL | AC3: PT | AD3: RO | AE3: SE | AF3: SI | AG3: SK | AH3: EU27_2020 | AI3: UA | AJ3: Leader value | AK3: Leader | AL3: Minimum (member states) | AM3: Eurostat DOI | AN3: Derzhstat link
A4: ERP | B4: C | C4: isoc_eb_iipn2 | D4: E_ERP1 | E4: 2025 | F4: 2025 | G4: 39.48 | I4: 20.79 | J4: 51.17 | K4: 48.16 | L4: 36.76 | N4: 37.23 | O4: 64.7 | P4: 66.42 | R4: 44.73 | S4: 16.52 | T4: 28.07 | U4: 40.95 | V4: 48.97 | W4: 59.21 | Y4: 45.3 | Z4: 51.12 | AA4: 56.49 | AB4: 37.18 | AD4: 21.02 | AE4: 28.82 | AF4: 23.51 | AG4: 21.08 | AH4: 45.06 | AI4: 20.4 | AJ4: =MAX(G4:AG4) -> 66.42 | AK4: =INDEX($G$3:$AG$3,MATCH(AJ4,G4:AG4,0)) -> ES | AL4: =MIN(G4:AG4) -> 16.52 | AM4: https://doi.org/10.2908/ISOC_EB_IIPN2 | AN4: https://stat.gov.ua/uk/explorer?urn=SSSU%3ADF_INFORM_COMMUN_TECH_ENTRP%28~%29
A5: IOT_PRODUCTION | B5: C | C5: isoc_eb_iotn2 | D5: E_IOTDPP | E5: 2021 | F5: 2022 | G5: 13.7 | I5: 5.36 | J5: 15.53 | K5: 15.03 | L5: 10.5 | M5: 4.82 | N5: 11.98 | O5: 5.78 | R5: 2.41 | S5: 3.9 | T5: 6.77 | U5: 11.38 | V5: 21.2 | W5: 13.88 | Y5: 14.43 | Z5: 16.37 | AA5: 9.17 | AB5: 6.4 | AC5: 2.28 | AD5: 3.04 | AE5: 19.37 | AF5: 17.6 | AG5: 11.25 | AH5: 9.68 | AI5: 2.2 | AJ5: =MAX(G5:AG5) -> 21.2 | AK5: =INDEX($G$3:$AG$3,MATCH(AJ5,G5:AG5,0)) -> IT | AL5: =MIN(G5:AG5) -> 2.28 | AM5: https://doi.org/10.2908/ISOC_EB_IOTN2 | AN5: https://stat.gov.ua/uk/explorer?urn=SSSU%3ADF_INFORM_COMMUN_TECH_ENTRP%28~%29
A6: ICT_SECURITY_DOCUMENT | B6: C | C6: isoc_cisce_ran2 | D6: E_SECPOL2 | E6: 2024 | F6: 2023 | G6: 16.94 | I6: 5.87 | J6: 23.67 | K6: 16.8 | L6: 25.81 | M6: 36.4 | N6: 40.14 | O6: 13.84 | P6: 30.13 | R6: 14.9 | S6: 9.32 | T6: 8.95 | U6: 65.85 | V6: 30.27 | W6: 35.41 | Y6: 50.69 | Z6: 16.51 | AA6: 34.67 | AB6: 30.78 | AC6: 53.98 | AD6: 56.74 | AE6: 34.96 | AF6: 31.73 | AG6: 13.44 | AH6: 26.68 | AI6: 7.3 | AJ6: =MAX(G6:AG6) -> 65.85 | AK6: =INDEX($G$3:$AG$3,MATCH(AJ6,G6:AG6,0)) -> IE | AL6: =MIN(G6:AG6) -> 5.87 | AM6: https://doi.org/10.2908/ISOC_CISCE_RAN2 | AN6: https://stat.gov.ua/uk/explorer?urn=SSSU%3ADF_INFORM_COMMUN_TECH_ENTRP%28~%29
A7: ICT_TRAINING_ICT_SPECIALISTS | B7: L1 | C7: isoc_ske_ittn2 | D7: E_ITSPT2 | E7: 2024 | F7: 2025 | G7: 11.97 | H7: 17.83 | I7: 2.11 | J7: 7.35 | K7: 7.5 | L7: 6.39 | M7: 13.25 | N7: 4.53 | O7: 6.84 | P7: 6.37 | R7: 3.13 | S7: 3.32 | T7: 5.78 | U7: 18.08 | V7: 6.21 | W7: 7.73 | Y7: 6.16 | Z7: 12.92 | AA7: 17.3 | AB7: 13.48 | AC7: 8.14 | AD7: 5.75 | AE7: 5.46 | AF7: 6.87 | AG7: 4.16 | AH7: 7.1 | AI7: 5 | AJ7: =MAX(G7:AG7) -> 18.08 | AK7: =INDEX($G$3:$AG$3,MATCH(AJ7,G7:AG7,0)) -> IE | AL7: =MIN(G7:AG7) -> 2.11 | AM7: https://doi.org/10.2908/ISOC_SKE_ITTN2 | AN7: https://stat.gov.ua/uk/explorer?urn=SSSU%3ADF_INFORM_COMMUN_TECH_ENTRP%28~%29
A8: ICT_TRAINING_OTHER_EMPLOYEES | B8: L1 | C8: isoc_ske_ittn2 | D8: E_ITUST2 | E8: 2024 | F8: 2025 | G8: 11.14 | H8: 32.41 | I8: 3.31 | J8: 19.74 | K8: 15.92 | L8: 13.32 | M8: 19.46 | N8: 16.59 | O8: 8.35 | P8: 21.08 | R8: 7.03 | S8: 11.54 | T8: 9.22 | U8: 33.89 | V8: 15.66 | W8: 11.97 | Y8: 6.63 | Z8: 23.69 | AA8: 23.72 | AB8: 17.33 | AC8: 26.75 | AD8: 5.59 | AE8: 18.39 | AF8: 19.77 | AG8: 8.13 | AH8: 14.36 | AI8: 6.5 | AJ8: =MAX(G8:AG8) -> 33.89 | AK8: =INDEX($G$3:$AG$3,MATCH(AJ8,G8:AG8,0)) -> IE | AL8: =MIN(G8:AG8) -> 3.31 | AM8: https://doi.org/10.2908/ISOC_SKE_ITTN2 | AN8: https://stat.gov.ua/uk/explorer?urn=SSSU%3ADF_INFORM_COMMUN_TECH_ENTRP%28~%29
A9: SUPPLY_CHAIN_DATA_EXCHANGE | B9: L2 | C9: isoc_eb_icsn2 | D9: E_SISC | E9: 2023 | F9: 2025 | G9: 25.73 | I9: 10.11 | J9: 8.77 | K9: 37.12 | L9: 26.65 | M9: 36.49 | N9: 32.43 | O9: 13.83 | R9: 19.35 | S9: 5.55 | U9: 35.87 | V9: 15.52 | W9: 27.11 | Y9: 20.34 | Z9: 13.18 | AA9: 37.45 | AB9: 23.63 | AC9: 20.25 | AD9: 9.78 | AE9: 14.93 | AF9: 52.82 | AG9: 34.14 | AH9: 23.16 | AI9: 31.6 | AJ9: =MAX(G9:AG9) -> 52.82 | AK9: =INDEX($G$3:$AG$3,MATCH(AJ9,G9:AG9,0)) -> SI | AL9: =MIN(G9:AG9) -> 5.55 | AM9: https://doi.org/10.2908/ISOC_EB_ICSN2 | AN9: https://stat.gov.ua/uk/explorer?urn=SSSU%3ADF_INFORM_COMMUN_TECH_ENTRP%28~%29
A10: DATA_ANALYTICS | B10: L2 | C10: isoc_eb_dan2 | D10: E_DA | E10: 2025 | F10: 2025 | G10: 19.32 | I10: 22.86 | J10: 47.21 | K10: 41.51 | L10: 33.79 | N10: 50.27 | O10: 36.33 | P10: 45.34 | R10: 31.46 | S10: 33.34 | T10: 42.83 | U10: 48.26 | V10: 50 | W10: 66.58 | Y10: 46.34 | Z10: 46.72 | AA10: 53.28 | AB10: 18.72 | AD10: 31.63 | AE10: 35.44 | AF10: 33.44 | AG10: 29.39 | AH10: 37.73 | AI10: 21.3 | AJ10: =MAX(G10:AG10) -> 66.58 | AK10: =INDEX($G$3:$AG$3,MATCH(AJ10,G10:AG10,0)) -> LT | AL10: =MIN(G10:AG10) -> 18.72 | AM10: https://doi.org/10.2908/ISOC_EB_DAN2 | AN10: https://stat.gov.ua/uk/explorer?urn=SSSU%3ADF_INFORM_COMMUN_TECH_ENTRP%28~%29
A11: IOT_ANY | B11: L2 | C11: isoc_eb_iotn2 | D11: E_IOT1 | E11: 2021 | F11: 2022 | I11: 15.28 | J11: 43.71 | K11: 34.29 | L11: 38.22 | M11: 24.38 | N11: 25.37 | O11: 23.44 | R11: 20.42 | S11: 22.37 | T11: 21.11 | U11: 40.67 | V11: 40.33 | W11: 37.8 | Y11: 30.05 | Z11: 34.88 | AA11: 29.12 | AB11: 15.84 | AC11: 16.76 | AD11: 10.11 | AE11: 49.89 | AF11: 46.66 | AG11: 35.54 | AH11: 29.43 | AI11: 9.4 | AJ11: =MAX(G11:AG11) -> 49.89 | AK11: =INDEX($G$3:$AG$3,MATCH(AJ11,G11:AG11,0)) -> SE | AL11: =MIN(G11:AG11) -> 10.11 | AM11: https://doi.org/10.2908/ISOC_EB_IOTN2 | AN11: https://stat.gov.ua/uk/explorer?urn=SSSU%3ADF_INFORM_COMMUN_TECH_ENTRP%28~%29
A12: MOBILE_INTERNET | B12: L3 | C12: isoc_cimobe_usen2 | D12: E_EMPMD2_GT0 | E12: 2024 | F12: 2023 | I12: 72.42 | J12: 87.13 | K12: 81.73 | L12: 86.34 | N12: 85.59 | O12: 64.55 | P12: 88.83 | R12: 79.46 | T12: 70.48 | U12: 89.95 | W12: 94.02 | Y12: 89.96 | Z12: 87.43 | AA12: 74.41 | AB12: 87.56 | AC12: 84.66 | AD12: 81.61 | AF12: 95.81 | AG12: 58.74 | AH12: 82.47 | AI12: 45.9 | AJ12: =MAX(G12:AG12) -> 95.81 | AK12: =INDEX($G$3:$AG$3,MATCH(AJ12,G12:AG12,0)) -> SI | AL12: =MIN(G12:AG12) -> 58.74 | AM12: https://doi.org/10.2908/ISOC_CIMOBE_USEN2 | AN12: https://stat.gov.ua/uk/explorer?urn=SSSU%3ADF_INFORM_COMMUN_TECH_ENTRP%28~%29
A13: PAID_CLOUD | B13: L3 | C13: isoc_cicce_usen2 | D13: E_CC | E13: 2025 | F13: 2025 | G13: 45.99 | I13: 11.32 | J13: 47.05 | K13: 42.58 | L13: 39.13 | N13: 65.76 | O13: 21.58 | P13: 35.36 | R13: 25.15 | S13: 29.31 | T13: 33.93 | U13: 71.23 | V13: 67.77 | W13: 58.23 | Y13: 33.37 | Z13: 57.71 | AA13: 62.97 | AB13: 45.08 | AC13: 33.02 | AD13: 18.73 | AE13: 64.58 | AF13: 32.28 | AG13: 35.09 | AH13: 40.88 | AI13: 16.9 | AJ13: =MAX(G13:AG13) -> 71.23 | AK13: =INDEX($G$3:$AG$3,MATCH(AJ13,G13:AG13,0)) -> IE | AL13: =MIN(G13:AG13) -> 11.32 | AM13: https://doi.org/10.2908/ISOC_CICCE_USEN2 | AN13: https://stat.gov.ua/uk/explorer?urn=SSSU%3ADF_INFORM_COMMUN_TECH_ENTRP%28~%29
A14: ECOMMERCE_SALES | B14: L4 | C14: isoc_ec_eseln2 | D14: E_AESELL | E14: 2025 | F14: 2025 | G14: 45.69 | I14: 14.76 | J14: 24.96 | K14: 40.98 | L14: 33.04 | N14: 46.96 | O14: 14.51 | P14: 52.06 | R14: 33.28 | S14: 18.59 | T14: 26.74 | U14: 60.76 | V14: 29.37 | W14: 60.44 | Y14: 41.87 | Z14: 31.23 | AA14: 62.2 | AB14: 19.19 | AD14: 21.05 | AE14: 50.49 | AF14: 37.9 | AG14: 42.72 | AH14: 34.16 | AI14: 16.8 | AJ14: =MAX(G14:AG14) -> 62.2 | AK14: =INDEX($G$3:$AG$3,MATCH(AJ14,G14:AG14,0)) -> NL | AL14: =MIN(G14:AG14) -> 14.51 | AM14: https://doi.org/10.2908/ISOC_EC_ESELN2 | AN14: https://stat.gov.ua/uk/explorer?urn=SSSU%3ADF_INFORM_COMMUN_TECH_ENTRP%28~%29
A15: WEBSITE | B15: L4 | C15: isoc_ciwebn2 | D15: E_WEB | E15: 2025 | F15: 2025 | G15: 82.38 | I15: 45.61 | J15: 60.54 | K15: 79.11 | L15: 87.9 | M15: 97.47 | N15: 69.47 | O15: 62.49 | P15: 85.84 | R15: 57.94 | S15: 37.97 | T15: 58.88 | U15: 82.14 | V15: 77.49 | W15: 81.57 | Y15: 67.79 | Z15: 73.75 | AA15: 90.77 | AB15: 57.15 | AD15: 50.19 | AE15: 91.5 | AF15: 82.94 | AG15: 72.42 | AH15: 71.83 | AI15: 43 | AJ15: =MAX(G15:AG15) -> 97.47 | AK15: =INDEX($G$3:$AG$3,MATCH(AJ15,G15:AG15,0)) -> DK | AL15: =MIN(G15:AG15) -> 37.97 | AM15: https://doi.org/10.2908/ISOC_CIWEBN2 | AN15: https://stat.gov.ua/uk/explorer?urn=SSSU%3ADF_INFORM_COMMUN_TECH_ENTRP%28~%29
A16: CRM | B16: L4 | C16: isoc_eb_iipn2 | D16: E_CRM1 | E16: 2025 | F16: 2025 | G16: 22.4 | I16: 6.67 | J16: 23.56 | K16: 30.18 | L16: 15.17 | M16: 18.31 | N16: 11.41 | O16: 12.65 | P16: 27.11 | R16: 15.77 | S16: 8.55 | T16: 12.58 | U16: 17.33 | V16: 14.78 | W16: 26.04 | Y16: 13.14 | Z16: 26.29 | AA16: 31.25 | AB16: 21.14 | AC16: 16.85 | AD16: 8.78 | AE16: 18 | AF16: 11.61 | AG16: 13.71 | AH16: 17.99 | AI16: 6.9 | AJ16: =MAX(G16:AG16) -> 31.25 | AK16: =INDEX($G$3:$AG$3,MATCH(AJ16,G16:AG16,0)) -> NL | AL16: =MIN(G16:AG16) -> 6.67 | AM16: https://doi.org/10.2908/ISOC_EB_IIPN2 | AN16: https://stat.gov.ua/uk/explorer?urn=SSSU%3ADF_INFORM_COMMUN_TECH_ENTRP%28~%29
A17: EINVOICE_AUTOMATED | B17: DM_I | C17: isoc_eb_icsn2 | D17: E_INV4S_AP | E17: 2023 | F17: 2025 | G17: 29.09 | I17: 19.93 | J17: 19.54 | K17: 35.18 | L17: 25.93 | M17: 59.51 | N17: 78.38 | O17: 17.63 | R17: 32.02 | S17: 55.17 | T17: 31.7 | U17: 55.41 | V17: 97.92 | W17: 43.99 | Y17: 38.2 | Z17: 24.71 | AA17: 41.55 | AB17: 16.13 | AC17: 27.08 | AD17: 43.09 | AE17: 62.26 | AF17: 60.58 | AG17: 37.93 | AH17: 41.5 | AI17: 37.8 | AJ17: =MAX(G17:AG17) -> 97.92 | AK17: =INDEX($G$3:$AG$3,MATCH(AJ17,G17:AG17,0)) -> IT | AL17: =MIN(G17:AG17) -> 16.13 | AM17: https://doi.org/10.2908/ISOC_EB_ICSN2 | AN17: https://stat.gov.ua/uk/explorer?urn=SSSU%3ADF_INFORM_COMMUN_TECH_ENTRP%28~%29
A18: BI | B18: DM_I | C18: isoc_eb_iipn2 | D18: E_ITBI | E18: 2025 | F18: 2025 | G18: 14.79 | I18: 6.17 | J18: 23.24 | K18: 13.49 | L18: 11.64 | M18: 30.85 | N18: 18.33 | O18: 12.22 | P18: 21.96 | R18: 11.01 | S18: 7.58 | T18: 5.99 | U18: 27.85 | V18: 22.03 | W18: 30.71 | Y18: 17.96 | Z18: 19.22 | AA18: 34.8 | AB18: 9.96 | AC18: 8.38 | AD18: 5.93 | AE18: 20.5 | AF18: 17.22 | AG18: 5.1 | AH18: 15.22 | AI18: 6.6 | AJ18: =MAX(G18:AG18) -> 34.8 | AK18: =INDEX($G$3:$AG$3,MATCH(AJ18,G18:AG18,0)) -> NL | AL18: =MIN(G18:AG18) -> 5.1 | AM18: https://doi.org/10.2908/ISOC_EB_IIPN2 | AN18: https://stat.gov.ua/uk/explorer?urn=SSSU%3ADF_INFORM_COMMUN_TECH_ENTRP%28~%29
A19: AI_ANY | B19: DM_S | C19: isoc_eb_ain2 | D19: E_AI_TANY | E19: 2025 | F19: 2025 | G19: 22.65 | I19: 4.72 | J19: 3.61 | K19: 10.78 | L19: 15.1 | M19: 26.48 | N19: 16.43 | O19: 3.84 | P19: 14.63 | R19: 10.75 | S19: 7.27 | T19: 6.05 | U19: 22.66 | V19: 15.32 | W19: 16.22 | Y19: 11.8 | Z19: 7.95 | AA19: 22.61 | AB19: 5.01 | AC19: 6.79 | AD19: 2.05 | AE19: 21.39 | AF19: 17.54 | AG19: 10.32 | AH19: 12.47 | AI19: 5 | AJ19: =MAX(G19:AG19) -> 26.48 | AK19: =INDEX($G$3:$AG$3,MATCH(AJ19,G19:AG19,0)) -> DK | AL19: =MIN(G19:AG19) -> 2.05 | AM19: https://doi.org/10.2908/ISOC_EB_AIN2 | AN19: https://stat.gov.ua/uk/explorer?urn=SSSU%3ADF_INFORM_COMMUN_TECH_ENTRP%28~%29
A20: DII_BASIC_V3 | B20: DM_S | C20: isoc_e_diin2 | D20: E_DI3_GELO | E20: 2025 | F20: 2025 | G20: 63.77 | I20: 28.38 | J20: 71.74 | K20: 66.15 | L20: 62.56 | M20: 91.19 | N20: 71.48 | O20: 56.24 | P20: 73.07 | Q20: 96.43 | R20: 49.63 | S20: 35.65 | T20: 50.96 | U20: 78.91 | V20: 73.41 | W20: 79.85 | Y20: 64.05 | Z20: 71.07 | AA20: 91.18 | AB20: 49.72 | AD20: 34.71 | AE20: 81.21 | AF20: 49.24 | AG20: 53.3 | AH20: 60.91 | AI20: 27.8 | AJ20: =MAX(G20:AG20) -> 96.43 | AK20: =INDEX($G$3:$AG$3,MATCH(AJ20,G20:AG20,0)) -> FI | AL20: =MIN(G20:AG20) -> 28.38 | AM20: https://doi.org/10.2908/ISOC_E_DIIN2 | AN20: https://stat.gov.ua/uk/explorer?urn=SSSU%3ADF_INFORM_COMMUN_TECH_ENTRP%28~%29

Sheet Processing_index
A1: Statistics mode: DM = P / P_leader, layers, ADMI, levels, ranks
A3: Unit | B3: ERP | C3: IOT_PRODUCTION | D3: ICT_SECURITY_DOCUMENT | E3: ICT_TRAINING_ICT_SPECIALISTS | F3: ICT_TRAINING_OTHER_EMPLOYEES | G3: SUPPLY_CHAIN_DATA_EXCHANGE | H3: DATA_ANALYTICS | I3: IOT_ANY | J3: MOBILE_INTERNET | K3: PAID_CLOUD | L3: ECOMMERCE_SALES | M3: WEBSITE | N3: CRM | O3: EINVOICE_AUTOMATED | P3: BI | Q3: AI_ANY | R3: DII_BASIC_V3 | S3: C | T3: L1 | U3: L2 | V3: L3 | W3: L4 | X3: DM_I | Y3: DM_S | Z3: ADMI_base | AA3: DM_min | AB3: Weakest layer | AC3: Penalty | AD3: ADMI | AE3: Level | AF3: Rank (9 CEE + UA)
A4: EU27_2020 | B4: =IF(Processing_data!$AH$4="","",Processing_data!$AH$4/Processing_data!$AJ$4) -> 0.67841012 | C4: =IF(Processing_data!$AH$5="","",Processing_data!$AH$5/Processing_data!$AJ$5) -> 0.45660377 | D4: =IF(Processing_data!$AH$6="","",Processing_data!$AH$6/Processing_data!$AJ$6) -> 0.40516325 | E4: =IF(Processing_data!$AH$7="","",Processing_data!$AH$7/Processing_data!$AJ$7) -> 0.39269912 | F4: =IF(Processing_data!$AH$8="","",Processing_data!$AH$8/Processing_data!$AJ$8) -> 0.42372381 | G4: =IF(Processing_data!$AH$9="","",Processing_data!$AH$9/Processing_data!$AJ$9) -> 0.43847028 | H4: =IF(Processing_data!$AH$10="","",Processing_data!$AH$10/Processing_data!$AJ$10) -> 0.56668669 | I4: =IF(Processing_data!$AH$11="","",Processing_data!$AH$11/Processing_data!$AJ$11) -> 0.58989778 | J4: =IF(Processing_data!$AH$12="","",Processing_data!$AH$12/Processing_data!$AJ$12) -> 0.8607661 | K4: =IF(Processing_data!$AH$13="","",Processing_data!$AH$13/Processing_data!$AJ$13) -> 0.57391549 | L4: =IF(Processing_data!$AH$14="","",Processing_data!$AH$14/Processing_data!$AJ$14) -> 0.54919614 | M4: =IF(Processing_data!$AH$15="","",Processing_data!$AH$15/Processing_data!$AJ$15) -> 0.7369447 | N4: =IF(Processing_data!$AH$16="","",Processing_data!$AH$16/Processing_data!$AJ$16) -> 0.57568 | O4: =IF(Processing_data!$AH$17="","",Processing_data!$AH$17/Processing_data!$AJ$17) -> 0.42381536 | P4: =IF(Processing_data!$AH$18="","",Processing_data!$AH$18/Processing_data!$AJ$18) -> 0.43735632 | Q4: =IF(Processing_data!$AH$19="","",Processing_data!$AH$19/Processing_data!$AJ$19) -> 0.47092145 | R4: =IF(Processing_data!$AH$20="","",Processing_data!$AH$20/Processing_data!$AJ$20) -> 0.6316499 | S4: =AVERAGE(B4:D4) -> 0.51339238 | T4: =AVERAGE(E4:F4) -> 0.40821146 | U4: =AVERAGE(G4:I4) -> 0.53168491 | V4: =AVERAGE(J4:K4) -> 0.71734079 | W4: =AVERAGE(L4:N4) -> 0.62060695 | X4: =AVERAGE(O4:P4) -> 0.43058584 | Y4: =AVERAGE(Q4:R4) -> 0.55128568 | Z4: =AVERAGE(S4:W4) -> 0.5582473 | AA4: =MIN(S4:W4) -> 0.40821146 | AB4: =INDEX($S$3:$W$3,MATCH(AA4,S4:W4,0)) -> L1 | AC4: =1-alpha*MAX(0,delta-AA4) -> 1 | AD4: =Z4*AC4 -> 0.5582473 | AE4: =1+COUNTIF(bounds,"<"&ROUND(AD4,12)) -> 3
A5: DE | B5: =IF(Processing_data!$L$4="","",Processing_data!$L$4/Processing_data!$AJ$4) -> 0.55344776 | C5: =IF(Processing_data!$L$5="","",Processing_data!$L$5/Processing_data!$AJ$5) -> 0.49528302 | D5: =IF(Processing_data!$L$6="","",Processing_data!$L$6/Processing_data!$AJ$6) -> 0.3919514 | E5: =IF(Processing_data!$L$7="","",Processing_data!$L$7/Processing_data!$AJ$7) -> 0.3534292 | F5: =IF(Processing_data!$L$8="","",Processing_data!$L$8/Processing_data!$AJ$8) -> 0.39303629 | G5: =IF(Processing_data!$L$9="","",Processing_data!$L$9/Processing_data!$AJ$9) -> 0.50454373 | H5: =IF(Processing_data!$L$10="","",Processing_data!$L$10/Processing_data!$AJ$10) -> 0.50750976 | I5: =IF(Processing_data!$L$11="","",Processing_data!$L$11/Processing_data!$AJ$11) -> 0.76608539 | J5: =IF(Processing_data!$L$12="","",Processing_data!$L$12/Processing_data!$AJ$12) -> 0.90115854 | K5: =IF(Processing_data!$L$13="","",Processing_data!$L$13/Processing_data!$AJ$13) -> 0.54934719 | L5: =IF(Processing_data!$L$14="","",Processing_data!$L$14/Processing_data!$AJ$14) -> 0.53118971 | M5: =IF(Processing_data!$L$15="","",Processing_data!$L$15/Processing_data!$AJ$15) -> 0.90181594 | N5: =IF(Processing_data!$L$16="","",Processing_data!$L$16/Processing_data!$AJ$16) -> 0.48544 | O5: =IF(Processing_data!$L$17="","",Processing_data!$L$17/Processing_data!$AJ$17) -> 0.26480801 | P5: =IF(Processing_data!$L$18="","",Processing_data!$L$18/Processing_data!$AJ$18) -> 0.33448276 | Q5: =IF(Processing_data!$L$19="","",Processing_data!$L$19/Processing_data!$AJ$19) -> 0.57024169 | R5: =IF(Processing_data!$L$20="","",Processing_data!$L$20/Processing_data!$AJ$20) -> 0.64876076 | S5: =AVERAGE(B5:D5) -> 0.48022739 | T5: =AVERAGE(E5:F5) -> 0.37323275 | U5: =AVERAGE(G5:I5) -> 0.59271296 | V5: =AVERAGE(J5:K5) -> 0.72525286 | W5: =AVERAGE(L5:N5) -> 0.63948188 | X5: =AVERAGE(O5:P5) -> 0.29964538 | Y5: =AVERAGE(Q5:R5) -> 0.60950123 | Z5: =AVERAGE(S5:W5) -> 0.56218157 | AA5: =MIN(S5:W5) -> 0.37323275 | AB5: =INDEX($S$3:$W$3,MATCH(AA5,S5:W5,0)) -> L1 | AC5: =1-alpha*MAX(0,delta-AA5) -> 0.9992931 | AD5: =Z5*AC5 -> 0.56178416 | AE5: =1+COUNTIF(bounds,"<"&ROUND(AD5,12)) -> 3
